Thread 1 "python" received signal SIGSEGV, Segmentation fault.
0x00007fffbab7a2c8 in tensorflow::TF_SessionReleaseCallable(TF_Session*, long, TF_Status*) ()
   from /home/edwisdom/tufts/reu/lib/python3.6/site-packages/tensorflow/python/_pywrap_tensorflow_internal.so
(gdb) bt
#0  0x00007fffbab7a2c8 in tensorflow::TF_SessionReleaseCallable(TF_Session*, long, TF_Status*) ()
   from /home/edwisdom/tufts/reu/lib/python3.6/site-packages/tensorflow/python/_pywrap_tensorflow_internal.so
#1  0x00007fffbab29512 in _wrap_TF_SessionReleaseCallable ()
   from /home/edwisdom/tufts/reu/lib/python3.6/site-packages/tensorflow/python/_pywrap_tensorflow_internal.so
#2  0x00007ffff73e8e23 in _PyCFunction_FastCallDict () from /usr/lib/libpython3.6m.so.1.0
#3  0x00007ffff73e59de in ?? () from /usr/lib/libpython3.6m.so.1.0
#4  0x00007ffff73b585a in _PyEval_EvalFrameDefault () from /usr/lib/libpython3.6m.so.1.0
#5  0x00007ffff73e4d3b in _PyFunction_FastCallDict () from /usr/lib/libpython3.6m.so.1.0
#6  0x00007ffff741d8df in _PyObject_FastCallDict () from /usr/lib/libpython3.6m.so.1.0
#7  0x00007ffff741e242 in _PyObject_Call_Prepend () from /usr/lib/libpython3.6m.so.1.0
#8  0x00007ffff741d64c in _PyObject_FastCallDict () from /usr/lib/libpython3.6m.so.1.0
#9  0x00007ffff73b1f96 in ?? () from /usr/lib/libpython3.6m.so.1.0
#10 0x00007ffff7386921 in ?? () from /usr/lib/libpython3.6m.so.1.0
#11 0x00007ffff74831fd in ?? () from /usr/lib/libpython3.6m.so.1.0
#12 0x00007ffff738713e in _PyObject_GC_Malloc () from /usr/lib/libpython3.6m.so.1.0
#13 0x00007ffff73871be in _PyObject_GC_New () from /usr/lib/libpython3.6m.so.1.0
#14 0x00007ffff7414656 in ?? () from /usr/lib/libpython3.6m.so.1.0
#15 0x00007ffff741cf06 in PyObject_GetIter () from /usr/lib/libpython3.6m.so.1.0
#16 0x00007ffff73b6349 in _PyEval_EvalFrameDefault () from /usr/lib/libpython3.6m.so.1.0
#17 0x00007ffff73e3ce9 in ?? () from /usr/lib/libpython3.6m.so.1.0
#18 0x00007ffff73e5690 in ?? () from /usr/lib/libpython3.6m.so.1.0